ERROR 2018-09-14 10:26:33,819 ldapop 41373 123145510801408 ldapop.py.status:33 {'desc': 'Invalid credentials'}
ERROR 2018-09-14 10:26:33,848 ldapop 41373 123145510801408 ldapop.py.status:33 {'desc': 'Invalid credentials'}
ERROR 2018-09-14 10:26:33,876 ldapop 41373 123145510801408 ldapop.py.status:33 {'desc': 'Invalid credentials'}
ERROR 2018-09-14 10:34:11,281 ldapop 41616 123145338560512 ldapop.py.status:33 {'desc': 'Invalid credentials'}
ERROR 2018-09-14 10:34:11,321 ldapop 41616 123145338560512 ldapop.py.status:33 {'desc': 'Invalid credentials'}
ERROR 2018-09-14 10:34:11,359 ldapop 41616 123145338560512 ldapop.py.status:33 {'desc': 'Invalid credentials'}
ERROR 2018-09-14 10:36:07,067 ldapop 41643 123145503506432 ldapop.py.status:33 {'desc': 'Invalid credentials'}
ERROR 2018-09-14 10:36:07,129 ldapop 41643 123145503506432 ldapop.py.status:33 {'desc': 'Invalid credentials'}
ERROR 2018-09-14 10:36:07,166 ldapop 41643 123145503506432 ldapop.py.status:33 {'desc': 'Invalid credentials'}
ERROR 2018-09-14 10:36:48,864 ldapop 41643 123145503506432 ldapop.py.status:33 {'desc': 'Invalid credentials'}
ERROR 2018-09-14 10:36:48,896 ldapop 41643 123145503506432 ldapop.py.status:33 {'desc': 'Invalid credentials'}
ERROR 2018-09-14 10:36:48,925 ldapop 41643 123145503506432 ldapop.py.status:33 {'desc': 'Invalid credentials'}
ERROR 2018-09-14 11:03:05,444 ldapop 42287 123145525760000 ldapop.py.__init__:19 {'desc': "Can't contact LDAP server"}
ERROR 2018-09-14 11:03:05,444 ldapop 42287 123145525760000 ldapop.py.status:33 {'desc': "Can't contact LDAP server"}
ERROR 2018-09-14 11:03:05,445 ldapop 42287 123145525760000 ldapop.py.status:33 {'desc': "Can't contact LDAP server"}
ERROR 2018-09-14 11:03:05,445 ldapop 42287 123145525760000 ldapop.py.status:33 {'desc': "Can't contact LDAP server"}
ERROR 2018-09-14 11:03:13,575 ldapop 42287 123145525760000 ldapop.py.__init__:19 {'desc': "Can't contact LDAP server"}
ERROR 2018-09-14 11:03:13,575 ldapop 42287 123145525760000 ldapop.py.status:33 {'desc': "Can't contact LDAP server"}
ERROR 2018-09-14 11:03:13,575 ldapop 42287 123145525760000 ldapop.py.status:33 {'desc': "Can't contact LDAP server"}
ERROR 2018-09-14 11:03:13,576 ldapop 42287 123145525760000 ldapop.py.status:33 {'desc': "Can't contact LDAP server"}
ERROR 2018-09-14 11:04:18,778 ldapop 42862 123145558605824 ldapop.py.__init__:19 {'desc': "Can't contact LDAP server"}
ERROR 2018-09-14 11:04:18,778 ldapop 42862 123145558605824 ldapop.py.status:33 {'desc': "Can't contact LDAP server"}
ERROR 2018-09-14 11:04:18,779 ldapop 42862 123145558605824 ldapop.py.status:33 {'desc': "Can't contact LDAP server"}
ERROR 2018-09-14 11:04:18,779 ldapop 42862 123145558605824 ldapop.py.status:33 {'desc': "Can't contact LDAP server"}
ERROR 2018-09-14 11:05:48,010 ldapop 42862 123145558069248 ldapop.py.__init__:19 {'desc': "Can't contact LDAP server"}
ERROR 2018-09-14 11:05:48,010 ldapop 42862 123145558069248 ldapop.py.status:33 {'desc': "Can't contact LDAP server"}
ERROR 2018-09-14 11:05:48,011 ldapop 42862 123145558069248 ldapop.py.status:33 {'desc': "Can't contact LDAP server"}
ERROR 2018-09-14 11:05:48,011 ldapop 42862 123145558069248 ldapop.py.status:33 {'desc': "Can't contact LDAP server"}
ERROR 2018-09-14 11:05:53,105 ldapop 42862 123145558069248 ldapop.py.__init__:19 {'desc': "Can't contact LDAP server"}
ERROR 2018-09-14 11:05:53,105 ldapop 42862 123145558069248 ldapop.py.status:33 {'desc': "Can't contact LDAP server"}
ERROR 2018-09-14 11:05:53,105 ldapop 42862 123145558069248 ldapop.py.status:33 {'desc': "Can't contact LDAP server"}
ERROR 2018-09-14 11:05:53,106 ldapop 42862 123145558069248 ldapop.py.status:33 {'desc': "Can't contact LDAP server"}
ERROR 2018-09-14 11:05:56,826 ldapop 42862 123145558069248 ldapop.py.__init__:19 {'desc': "Can't contact LDAP server"}
ERROR 2018-09-14 11:05:56,827 ldapop 42862 123145558069248 ldapop.py.status:33 {'desc': "Can't contact LDAP server"}
ERROR 2018-09-14 11:05:56,827 ldapop 42862 123145558069248 ldapop.py.status:33 {'desc': "Can't contact LDAP server"}
ERROR 2018-09-14 11:05:56,827 ldapop 42862 123145558069248 ldapop.py.status:33 {'desc': "Can't contact LDAP server"}
ERROR 2018-09-14 11:06:00,013 ldapop 42862 123145558069248 ldapop.py.__init__:19 {'desc': "Can't contact LDAP server"}
ERROR 2018-09-14 11:06:00,013 ldapop 42862 123145558069248 ldapop.py.status:33 {'desc': "Can't contact LDAP server"}
ERROR 2018-09-14 11:06:00,013 ldapop 42862 123145558069248 ldapop.py.status:33 {'desc': "Can't contact LDAP server"}
ERROR 2018-09-14 11:06:00,013 ldapop 42862 123145558069248 ldapop.py.status:33 {'desc': "Can't contact LDAP server"}
ERROR 2018-09-14 11:11:23,457 ldapop 43156 123145511399424 ldapop.py.__init__:19 {'desc': "Can't contact LDAP server"}
ERROR 2018-09-14 11:11:23,458 ldapop 43156 123145511399424 ldapop.py.status:33 {'desc': "Can't contact LDAP server"}
ERROR 2018-09-14 11:11:23,458 ldapop 43156 123145511399424 ldapop.py.status:33 {'desc': "Can't contact LDAP server"}
ERROR 2018-09-14 11:11:23,458 ldapop 43156 123145511399424 ldapop.py.status:33 {'desc': "Can't contact LDAP server"}
ERROR 2018-09-14 11:11:36,095 ldapop 43156 123145511399424 ldapop.py.__init__:19 {'desc': "Can't contact LDAP server"}
ERROR 2018-09-14 11:11:36,097 ldapop 43156 123145511399424 ldapop.py.status:33 {'desc': "Can't contact LDAP server"}
ERROR 2018-09-14 11:11:36,097 ldapop 43156 123145511399424 ldapop.py.status:33 {'desc': "Can't contact LDAP server"}
ERROR 2018-09-14 11:11:36,097 ldapop 43156 123145511399424 ldapop.py.status:33 {'desc': "Can't contact LDAP server"}
ERROR 2018-09-14 11:20:22,046 ldapop 43640 123145363177472 ldapop.py.__init__:19 {'desc': "Can't contact LDAP server"}
ERROR 2018-09-14 11:20:22,046 ldapop 43640 123145363177472 ldapop.py.status:33 {'desc': "Can't contact LDAP server"}
ERROR 2018-09-14 11:20:22,047 ldapop 43640 123145363177472 ldapop.py.status:33 {'desc': "Can't contact LDAP server"}
ERROR 2018-09-14 11:20:22,047 ldapop 43640 123145363177472 ldapop.py.status:33 {'desc': "Can't contact LDAP server"}
ERROR 2018-09-14 11:31:26,099 ldapop 44253 123145432006656 ldapop.py.status:33 {'desc': 'Invalid credentials'}
ERROR 2018-09-14 11:31:26,138 ldapop 44253 123145432006656 ldapop.py.status:33 {'desc': 'Invalid credentials'}
ERROR 2018-09-14 11:31:26,170 ldapop 44253 123145432006656 ldapop.py.status:33 {'desc': 'Invalid credentials'}
ERROR 2018-09-14 11:31:58,846 views 44288 123145450954752 views.py.post:58 Object type <type 'unicode'> cannot be passed to C code
ERROR 2018-09-14 11:33:53,738 views 44376 123145370161152 views.py.post:58 Object type <type 'unicode'> cannot be passed to C code
ERROR 2018-09-14 11:34:28,829 views 44437 123145407397888 views.py.post:58 Object type <type 'unicode'> cannot be passed to C code
ERROR 2018-09-14 11:37:53,218 views 44491 123145353756672 views.py.post:64 local variable 'aes' referenced before assignment
ERROR 2018-09-14 11:38:28,423 views 44511 123145559179264 views.py.post:63 (1054, "Unknown column 'sys_admin' in 'field list'")
